{
 "cells": [
  {
   "cell_type": "code",
   "execution_count": 9,
   "id": "469a1fd3",
   "metadata": {},
   "outputs": [],
   "source": [
    "import re\n",
    "import datetime\n",
    "import time\n",
    "import paramiko\n",
    "from openpyxl import load_workbook"
   ]
  },
  {
   "cell_type": "code",
   "execution_count": 27,
   "id": "06732d0f",
   "metadata": {},
   "outputs": [],
   "source": [
    "server ='192.168.52.104'\n",
    "username='administrador'\n",
    "password='WDV55efb'\n"
   ]
  },
  {
   "cell_type": "code",
   "execution_count": 29,
   "id": "d2c56220",
   "metadata": {},
   "outputs": [
    {
     "ename": "TimeoutError",
     "evalue": "[WinError 10060] Se produjo un error durante el intento de conexión ya que la parte conectada no respondió adecuadamente tras un periodo de tiempo, o bien se produjo un error en la conexión establecida ya que el host conectado no ha podido responder",
     "output_type": "error",
     "traceback": [
      "\u001b[1;31m---------------------------------------------------------------------------\u001b[0m",
      "\u001b[1;31mTimeoutError\u001b[0m                              Traceback (most recent call last)",
      "\u001b[1;32m~\\AppData\\Local\\Temp\\ipykernel_17768\\615785075.py\u001b[0m in \u001b[0;36m<module>\u001b[1;34m\u001b[0m\n\u001b[0;32m      1\u001b[0m \u001b[0mssh\u001b[0m \u001b[1;33m=\u001b[0m \u001b[0mparamiko\u001b[0m\u001b[1;33m.\u001b[0m\u001b[0mSSHClient\u001b[0m\u001b[1;33m(\u001b[0m\u001b[1;33m)\u001b[0m\u001b[1;33m\u001b[0m\u001b[1;33m\u001b[0m\u001b[0m\n\u001b[1;32m----> 2\u001b[1;33m \u001b[0mssh\u001b[0m\u001b[1;33m.\u001b[0m\u001b[0mconnect\u001b[0m\u001b[1;33m(\u001b[0m\u001b[0mserver\u001b[0m\u001b[1;33m,\u001b[0m \u001b[0musername\u001b[0m\u001b[1;33m=\u001b[0m\u001b[0musername\u001b[0m\u001b[1;33m,\u001b[0m \u001b[0mpassword\u001b[0m\u001b[1;33m=\u001b[0m\u001b[0mpassword\u001b[0m\u001b[1;33m)\u001b[0m\u001b[1;33m\u001b[0m\u001b[1;33m\u001b[0m\u001b[0m\n\u001b[0m\u001b[0;32m      3\u001b[0m \u001b[0mssh_stdin\u001b[0m\u001b[1;33m,\u001b[0m \u001b[0mssh_stdout\u001b[0m\u001b[1;33m,\u001b[0m \u001b[0mssh_stderr\u001b[0m \u001b[1;33m=\u001b[0m \u001b[0mssh\u001b[0m\u001b[1;33m.\u001b[0m\u001b[0mexec_command\u001b[0m\u001b[1;33m(\u001b[0m\u001b[0mcmd_to_execute\u001b[0m\u001b[1;33m)\u001b[0m\u001b[1;33m\u001b[0m\u001b[1;33m\u001b[0m\u001b[0m\n",
      "\u001b[1;32m~\\.conda\\envs\\firma\\lib\\site-packages\\paramiko\\client.py\u001b[0m in \u001b[0;36mconnect\u001b[1;34m(self, hostname, port, username, password, pkey, key_filename, timeout, allow_agent, look_for_keys, compress, sock, gss_auth, gss_kex, gss_deleg_creds, gss_host, banner_timeout, auth_timeout, gss_trust_dns, passphrase, disabled_algorithms)\u001b[0m\n\u001b[0;32m    347\u001b[0m                         \u001b[1;32mexcept\u001b[0m\u001b[1;33m:\u001b[0m\u001b[1;33m\u001b[0m\u001b[1;33m\u001b[0m\u001b[0m\n\u001b[0;32m    348\u001b[0m                             \u001b[1;32mpass\u001b[0m\u001b[1;33m\u001b[0m\u001b[1;33m\u001b[0m\u001b[0m\n\u001b[1;32m--> 349\u001b[1;33m                     \u001b[0mretry_on_signal\u001b[0m\u001b[1;33m(\u001b[0m\u001b[1;32mlambda\u001b[0m\u001b[1;33m:\u001b[0m \u001b[0msock\u001b[0m\u001b[1;33m.\u001b[0m\u001b[0mconnect\u001b[0m\u001b[1;33m(\u001b[0m\u001b[0maddr\u001b[0m\u001b[1;33m)\u001b[0m\u001b[1;33m)\u001b[0m\u001b[1;33m\u001b[0m\u001b[1;33m\u001b[0m\u001b[0m\n\u001b[0m\u001b[0;32m    350\u001b[0m                     \u001b[1;31m# Break out of the loop on success\u001b[0m\u001b[1;33m\u001b[0m\u001b[1;33m\u001b[0m\u001b[1;33m\u001b[0m\u001b[0m\n\u001b[0;32m    351\u001b[0m                     \u001b[1;32mbreak\u001b[0m\u001b[1;33m\u001b[0m\u001b[1;33m\u001b[0m\u001b[0m\n",
      "\u001b[1;32m~\\.conda\\envs\\firma\\lib\\site-packages\\paramiko\\util.py\u001b[0m in \u001b[0;36mretry_on_signal\u001b[1;34m(function)\u001b[0m\n\u001b[0;32m    281\u001b[0m     \u001b[1;32mwhile\u001b[0m \u001b[1;32mTrue\u001b[0m\u001b[1;33m:\u001b[0m\u001b[1;33m\u001b[0m\u001b[1;33m\u001b[0m\u001b[0m\n\u001b[0;32m    282\u001b[0m         \u001b[1;32mtry\u001b[0m\u001b[1;33m:\u001b[0m\u001b[1;33m\u001b[0m\u001b[1;33m\u001b[0m\u001b[0m\n\u001b[1;32m--> 283\u001b[1;33m             \u001b[1;32mreturn\u001b[0m \u001b[0mfunction\u001b[0m\u001b[1;33m(\u001b[0m\u001b[1;33m)\u001b[0m\u001b[1;33m\u001b[0m\u001b[1;33m\u001b[0m\u001b[0m\n\u001b[0m\u001b[0;32m    284\u001b[0m         \u001b[1;32mexcept\u001b[0m \u001b[0mEnvironmentError\u001b[0m \u001b[1;32mas\u001b[0m \u001b[0me\u001b[0m\u001b[1;33m:\u001b[0m\u001b[1;33m\u001b[0m\u001b[1;33m\u001b[0m\u001b[0m\n\u001b[0;32m    285\u001b[0m             \u001b[1;32mif\u001b[0m \u001b[0me\u001b[0m\u001b[1;33m.\u001b[0m\u001b[0merrno\u001b[0m \u001b[1;33m!=\u001b[0m \u001b[0merrno\u001b[0m\u001b[1;33m.\u001b[0m\u001b[0mEINTR\u001b[0m\u001b[1;33m:\u001b[0m\u001b[1;33m\u001b[0m\u001b[1;33m\u001b[0m\u001b[0m\n",
      "\u001b[1;32m~\\.conda\\envs\\firma\\lib\\site-packages\\paramiko\\client.py\u001b[0m in \u001b[0;36m<lambda>\u001b[1;34m()\u001b[0m\n\u001b[0;32m    347\u001b[0m                         \u001b[1;32mexcept\u001b[0m\u001b[1;33m:\u001b[0m\u001b[1;33m\u001b[0m\u001b[1;33m\u001b[0m\u001b[0m\n\u001b[0;32m    348\u001b[0m                             \u001b[1;32mpass\u001b[0m\u001b[1;33m\u001b[0m\u001b[1;33m\u001b[0m\u001b[0m\n\u001b[1;32m--> 349\u001b[1;33m                     \u001b[0mretry_on_signal\u001b[0m\u001b[1;33m(\u001b[0m\u001b[1;32mlambda\u001b[0m\u001b[1;33m:\u001b[0m \u001b[0msock\u001b[0m\u001b[1;33m.\u001b[0m\u001b[0mconnect\u001b[0m\u001b[1;33m(\u001b[0m\u001b[0maddr\u001b[0m\u001b[1;33m)\u001b[0m\u001b[1;33m)\u001b[0m\u001b[1;33m\u001b[0m\u001b[1;33m\u001b[0m\u001b[0m\n\u001b[0m\u001b[0;32m    350\u001b[0m                     \u001b[1;31m# Break out of the loop on success\u001b[0m\u001b[1;33m\u001b[0m\u001b[1;33m\u001b[0m\u001b[1;33m\u001b[0m\u001b[0m\n\u001b[0;32m    351\u001b[0m                     \u001b[1;32mbreak\u001b[0m\u001b[1;33m\u001b[0m\u001b[1;33m\u001b[0m\u001b[0m\n",
      "\u001b[1;31mTimeoutError\u001b[0m: [WinError 10060] Se produjo un error durante el intento de conexión ya que la parte conectada no respondió adecuadamente tras un periodo de tiempo, o bien se produjo un error en la conexión establecida ya que el host conectado no ha podido responder"
     ]
    }
   ],
   "source": [
    "ssh = paramiko.SSHClient()\n",
    "ssh.connect(server, username=username, password=password)\n",
    "ssh_stdin, ssh_stdout, ssh_stderr = ssh.exec_command(cmd_to_execute)"
   ]
  },
  {
   "cell_type": "code",
   "execution_count": 30,
   "id": "fec4b462",
   "metadata": {},
   "outputs": [],
   "source": [
    "import getpass\n",
    "\n",
    "import paramiko\n",
    "\n",
    "import sys"
   ]
  },
  {
   "cell_type": "code",
   "execution_count": 35,
   "id": "e19e09f2",
   "metadata": {},
   "outputs": [
    {
     "name": "stdout",
     "output_type": "stream",
     "text": [
      "Nombre o ip del host: 192.168.52.104\n",
      "Usuario: Administrador\n",
      "········\n"
     ]
    },
    {
     "name": "stderr",
     "output_type": "stream",
     "text": [
      "ERROR:root:Internal Python error in the inspect module.\n",
      "Below is the traceback from this internal error.\n",
      "\n"
     ]
    },
    {
     "name": "stdout",
     "output_type": "stream",
     "text": [
      "Error en la conexión\n",
      "Traceback (most recent call last):\n",
      "  File \"C:\\Users\\adm-a202781\\AppData\\Local\\Temp\\ipykernel_17768\\88411200.py\", line 39, in conecta\n",
      "    self.CLIENT.connect( hostname = self.HOST , username = self.USERNAME , password = self.PASSWORD )\n",
      "  File \"C:\\Users\\adm-a202781\\.conda\\envs\\firma\\lib\\site-packages\\paramiko\\client.py\", line 349, in connect\n",
      "    retry_on_signal(lambda: sock.connect(addr))\n",
      "  File \"C:\\Users\\adm-a202781\\.conda\\envs\\firma\\lib\\site-packages\\paramiko\\util.py\", line 283, in retry_on_signal\n",
      "    return function()\n",
      "  File \"C:\\Users\\adm-a202781\\.conda\\envs\\firma\\lib\\site-packages\\paramiko\\client.py\", line 349, in <lambda>\n",
      "    retry_on_signal(lambda: sock.connect(addr))\n",
      "TimeoutError: [WinError 10060] Se produjo un error durante el intento de conexión ya que la parte conectada no respondió adecuadamente tras un periodo de tiempo, o bien se produjo un error en la conexión establecida ya que el host conectado no ha podido responder\n",
      "\n",
      "During handling of the above exception, another exception occurred:\n",
      "\n",
      "Traceback (most recent call last):\n",
      "  File \"C:\\Users\\adm-a202781\\.conda\\envs\\firma\\lib\\site-packages\\IPython\\core\\interactiveshell.py\", line 3524, in run_code\n",
      "    exec(code_obj, self.user_global_ns, self.user_ns)\n",
      "  File \"C:\\Users\\adm-a202781\\AppData\\Local\\Temp\\ipykernel_17768\\88411200.py\", line 89, in <module>\n",
      "    ssh.conecta()\n",
      "  File \"C:\\Users\\adm-a202781\\AppData\\Local\\Temp\\ipykernel_17768\\88411200.py\", line 45, in conecta\n",
      "    sys.exit(1)\n",
      "SystemExit: 1\n",
      "\n",
      "During handling of the above exception, another exception occurred:\n",
      "\n",
      "Traceback (most recent call last):\n",
      "  File \"C:\\Users\\adm-a202781\\.conda\\envs\\firma\\lib\\site-packages\\IPython\\core\\ultratb.py\", line 1101, in get_records\n",
      "    return _fixed_getinnerframes(etb, number_of_lines_of_context, tb_offset)\n",
      "  File \"C:\\Users\\adm-a202781\\.conda\\envs\\firma\\lib\\site-packages\\IPython\\core\\ultratb.py\", line 248, in wrapped\n",
      "    return f(*args, **kwargs)\n",
      "  File \"C:\\Users\\adm-a202781\\.conda\\envs\\firma\\lib\\site-packages\\IPython\\core\\ultratb.py\", line 281, in _fixed_getinnerframes\n",
      "    records = fix_frame_records_filenames(inspect.getinnerframes(etb, context))\n",
      "  File \"C:\\Users\\adm-a202781\\.conda\\envs\\firma\\lib\\inspect.py\", line 1502, in getinnerframes\n",
      "    frameinfo = (tb.tb_frame,) + getframeinfo(tb, context)\n",
      "AttributeError: 'tuple' object has no attribute 'tb_frame'\n"
     ]
    },
    {
     "ename": "TypeError",
     "evalue": "object of type 'NoneType' has no len()",
     "output_type": "error",
     "traceback": [
      "\u001b[1;31m---------------------------------------------------------------------------\u001b[0m",
      "\u001b[1;31mTimeoutError\u001b[0m                              Traceback (most recent call last)",
      "\u001b[1;32m~\\AppData\\Local\\Temp\\ipykernel_17768\\88411200.py\u001b[0m in \u001b[0;36mconecta\u001b[1;34m(self)\u001b[0m\n\u001b[0;32m     38\u001b[0m \u001b[1;33m\u001b[0m\u001b[0m\n\u001b[1;32m---> 39\u001b[1;33m             \u001b[0mself\u001b[0m\u001b[1;33m.\u001b[0m\u001b[0mCLIENT\u001b[0m\u001b[1;33m.\u001b[0m\u001b[0mconnect\u001b[0m\u001b[1;33m(\u001b[0m \u001b[0mhostname\u001b[0m \u001b[1;33m=\u001b[0m \u001b[0mself\u001b[0m\u001b[1;33m.\u001b[0m\u001b[0mHOST\u001b[0m \u001b[1;33m,\u001b[0m \u001b[0musername\u001b[0m \u001b[1;33m=\u001b[0m \u001b[0mself\u001b[0m\u001b[1;33m.\u001b[0m\u001b[0mUSERNAME\u001b[0m \u001b[1;33m,\u001b[0m \u001b[0mpassword\u001b[0m \u001b[1;33m=\u001b[0m \u001b[0mself\u001b[0m\u001b[1;33m.\u001b[0m\u001b[0mPASSWORD\u001b[0m \u001b[1;33m)\u001b[0m\u001b[1;33m\u001b[0m\u001b[1;33m\u001b[0m\u001b[0m\n\u001b[0m\u001b[0;32m     40\u001b[0m \u001b[1;33m\u001b[0m\u001b[0m\n",
      "\u001b[1;32m~\\.conda\\envs\\firma\\lib\\site-packages\\paramiko\\client.py\u001b[0m in \u001b[0;36mconnect\u001b[1;34m(self, hostname, port, username, password, pkey, key_filename, timeout, allow_agent, look_for_keys, compress, sock, gss_auth, gss_kex, gss_deleg_creds, gss_host, banner_timeout, auth_timeout, gss_trust_dns, passphrase, disabled_algorithms)\u001b[0m\n\u001b[0;32m    348\u001b[0m                             \u001b[1;32mpass\u001b[0m\u001b[1;33m\u001b[0m\u001b[1;33m\u001b[0m\u001b[0m\n\u001b[1;32m--> 349\u001b[1;33m                     \u001b[0mretry_on_signal\u001b[0m\u001b[1;33m(\u001b[0m\u001b[1;32mlambda\u001b[0m\u001b[1;33m:\u001b[0m \u001b[0msock\u001b[0m\u001b[1;33m.\u001b[0m\u001b[0mconnect\u001b[0m\u001b[1;33m(\u001b[0m\u001b[0maddr\u001b[0m\u001b[1;33m)\u001b[0m\u001b[1;33m)\u001b[0m\u001b[1;33m\u001b[0m\u001b[1;33m\u001b[0m\u001b[0m\n\u001b[0m\u001b[0;32m    350\u001b[0m                     \u001b[1;31m# Break out of the loop on success\u001b[0m\u001b[1;33m\u001b[0m\u001b[1;33m\u001b[0m\u001b[1;33m\u001b[0m\u001b[0m\n",
      "\u001b[1;32m~\\.conda\\envs\\firma\\lib\\site-packages\\paramiko\\util.py\u001b[0m in \u001b[0;36mretry_on_signal\u001b[1;34m(function)\u001b[0m\n\u001b[0;32m    282\u001b[0m         \u001b[1;32mtry\u001b[0m\u001b[1;33m:\u001b[0m\u001b[1;33m\u001b[0m\u001b[1;33m\u001b[0m\u001b[0m\n\u001b[1;32m--> 283\u001b[1;33m             \u001b[1;32mreturn\u001b[0m \u001b[0mfunction\u001b[0m\u001b[1;33m(\u001b[0m\u001b[1;33m)\u001b[0m\u001b[1;33m\u001b[0m\u001b[1;33m\u001b[0m\u001b[0m\n\u001b[0m\u001b[0;32m    284\u001b[0m         \u001b[1;32mexcept\u001b[0m \u001b[0mEnvironmentError\u001b[0m \u001b[1;32mas\u001b[0m \u001b[0me\u001b[0m\u001b[1;33m:\u001b[0m\u001b[1;33m\u001b[0m\u001b[1;33m\u001b[0m\u001b[0m\n",
      "\u001b[1;32m~\\.conda\\envs\\firma\\lib\\site-packages\\paramiko\\client.py\u001b[0m in \u001b[0;36m<lambda>\u001b[1;34m()\u001b[0m\n\u001b[0;32m    348\u001b[0m                             \u001b[1;32mpass\u001b[0m\u001b[1;33m\u001b[0m\u001b[1;33m\u001b[0m\u001b[0m\n\u001b[1;32m--> 349\u001b[1;33m                     \u001b[0mretry_on_signal\u001b[0m\u001b[1;33m(\u001b[0m\u001b[1;32mlambda\u001b[0m\u001b[1;33m:\u001b[0m \u001b[0msock\u001b[0m\u001b[1;33m.\u001b[0m\u001b[0mconnect\u001b[0m\u001b[1;33m(\u001b[0m\u001b[0maddr\u001b[0m\u001b[1;33m)\u001b[0m\u001b[1;33m)\u001b[0m\u001b[1;33m\u001b[0m\u001b[1;33m\u001b[0m\u001b[0m\n\u001b[0m\u001b[0;32m    350\u001b[0m                     \u001b[1;31m# Break out of the loop on success\u001b[0m\u001b[1;33m\u001b[0m\u001b[1;33m\u001b[0m\u001b[1;33m\u001b[0m\u001b[0m\n",
      "\u001b[1;31mTimeoutError\u001b[0m: [WinError 10060] Se produjo un error durante el intento de conexión ya que la parte conectada no respondió adecuadamente tras un periodo de tiempo, o bien se produjo un error en la conexión establecida ya que el host conectado no ha podido responder",
      "\nDuring handling of the above exception, another exception occurred:\n",
      "\u001b[1;31mSystemExit\u001b[0m                                Traceback (most recent call last)",
      "    \u001b[1;31m[... skipping hidden 1 frame]\u001b[0m\n",
      "\u001b[1;32m~\\AppData\\Local\\Temp\\ipykernel_17768\\88411200.py\u001b[0m in \u001b[0;36m<module>\u001b[1;34m\u001b[0m\n\u001b[0;32m     88\u001b[0m \u001b[1;33m\u001b[0m\u001b[0m\n\u001b[1;32m---> 89\u001b[1;33m     \u001b[0mssh\u001b[0m\u001b[1;33m.\u001b[0m\u001b[0mconecta\u001b[0m\u001b[1;33m(\u001b[0m\u001b[1;33m)\u001b[0m\u001b[1;33m\u001b[0m\u001b[1;33m\u001b[0m\u001b[0m\n\u001b[0m",
      "\u001b[1;32m~\\AppData\\Local\\Temp\\ipykernel_17768\\88411200.py\u001b[0m in \u001b[0;36mconecta\u001b[1;34m(self)\u001b[0m\n\u001b[0;32m     44\u001b[0m \u001b[1;33m\u001b[0m\u001b[0m\n\u001b[1;32m---> 45\u001b[1;33m             \u001b[0msys\u001b[0m\u001b[1;33m.\u001b[0m\u001b[0mexit\u001b[0m\u001b[1;33m(\u001b[0m\u001b[1;36m1\u001b[0m\u001b[1;33m)\u001b[0m\u001b[1;33m\u001b[0m\u001b[1;33m\u001b[0m\u001b[0m\n\u001b[0m\u001b[0;32m     46\u001b[0m \u001b[1;33m\u001b[0m\u001b[0m\n",
      "\u001b[1;31mSystemExit\u001b[0m: 1",
      "\nDuring handling of the above exception, another exception occurred:\n",
      "\u001b[1;31mTypeError\u001b[0m                                 Traceback (most recent call last)",
      "    \u001b[1;31m[... skipping hidden 1 frame]\u001b[0m\n",
      "\u001b[1;32m~\\.conda\\envs\\firma\\lib\\site-packages\\IPython\\core\\interactiveshell.py\u001b[0m in \u001b[0;36mshowtraceback\u001b[1;34m(self, exc_tuple, filename, tb_offset, exception_only, running_compiled_code)\u001b[0m\n\u001b[0;32m   2080\u001b[0m                            'the full traceback.\\n']\n\u001b[0;32m   2081\u001b[0m                     stb.extend(self.InteractiveTB.get_exception_only(etype,\n\u001b[1;32m-> 2082\u001b[1;33m                                                                      value))\n\u001b[0m\u001b[0;32m   2083\u001b[0m                 \u001b[1;32melse\u001b[0m\u001b[1;33m:\u001b[0m\u001b[1;33m\u001b[0m\u001b[1;33m\u001b[0m\u001b[0m\n\u001b[0;32m   2084\u001b[0m                     \u001b[1;32mtry\u001b[0m\u001b[1;33m:\u001b[0m\u001b[1;33m\u001b[0m\u001b[1;33m\u001b[0m\u001b[0m\n",
      "\u001b[1;32m~\\.conda\\envs\\firma\\lib\\site-packages\\IPython\\core\\ultratb.py\u001b[0m in \u001b[0;36mget_exception_only\u001b[1;34m(self, etype, value)\u001b[0m\n\u001b[0;32m    752\u001b[0m         \u001b[0mvalue\u001b[0m \u001b[1;33m:\u001b[0m \u001b[0mexception\u001b[0m \u001b[0mvalue\u001b[0m\u001b[1;33m\u001b[0m\u001b[1;33m\u001b[0m\u001b[0m\n\u001b[0;32m    753\u001b[0m         \"\"\"\n\u001b[1;32m--> 754\u001b[1;33m         \u001b[1;32mreturn\u001b[0m \u001b[0mListTB\u001b[0m\u001b[1;33m.\u001b[0m\u001b[0mstructured_traceback\u001b[0m\u001b[1;33m(\u001b[0m\u001b[0mself\u001b[0m\u001b[1;33m,\u001b[0m \u001b[0metype\u001b[0m\u001b[1;33m,\u001b[0m \u001b[0mvalue\u001b[0m\u001b[1;33m)\u001b[0m\u001b[1;33m\u001b[0m\u001b[1;33m\u001b[0m\u001b[0m\n\u001b[0m\u001b[0;32m    755\u001b[0m \u001b[1;33m\u001b[0m\u001b[0m\n\u001b[0;32m    756\u001b[0m     \u001b[1;32mdef\u001b[0m \u001b[0mshow_exception_only\u001b[0m\u001b[1;33m(\u001b[0m\u001b[0mself\u001b[0m\u001b[1;33m,\u001b[0m \u001b[0metype\u001b[0m\u001b[1;33m,\u001b[0m \u001b[0mevalue\u001b[0m\u001b[1;33m)\u001b[0m\u001b[1;33m:\u001b[0m\u001b[1;33m\u001b[0m\u001b[1;33m\u001b[0m\u001b[0m\n",
      "\u001b[1;32m~\\.conda\\envs\\firma\\lib\\site-packages\\IPython\\core\\ultratb.py\u001b[0m in \u001b[0;36mstructured_traceback\u001b[1;34m(self, etype, evalue, etb, tb_offset, context)\u001b[0m\n\u001b[0;32m    631\u001b[0m                     chained_exceptions_tb_offset, context)\n\u001b[0;32m    632\u001b[0m                 \u001b[1;33m+\u001b[0m \u001b[0mchained_exception_message\u001b[0m\u001b[1;33m\u001b[0m\u001b[1;33m\u001b[0m\u001b[0m\n\u001b[1;32m--> 633\u001b[1;33m                 + out_list)\n\u001b[0m\u001b[0;32m    634\u001b[0m \u001b[1;33m\u001b[0m\u001b[0m\n\u001b[0;32m    635\u001b[0m         \u001b[1;32mreturn\u001b[0m \u001b[0mout_list\u001b[0m\u001b[1;33m\u001b[0m\u001b[1;33m\u001b[0m\u001b[0m\n",
      "\u001b[1;32m~\\.conda\\envs\\firma\\lib\\site-packages\\IPython\\core\\ultratb.py\u001b[0m in \u001b[0;36mstructured_traceback\u001b[1;34m(self, etype, value, tb, tb_offset, number_of_lines_of_context)\u001b[0m\n\u001b[0;32m   1366\u001b[0m             \u001b[0mself\u001b[0m\u001b[1;33m.\u001b[0m\u001b[0mtb\u001b[0m \u001b[1;33m=\u001b[0m \u001b[0mtb\u001b[0m\u001b[1;33m\u001b[0m\u001b[1;33m\u001b[0m\u001b[0m\n\u001b[0;32m   1367\u001b[0m         return FormattedTB.structured_traceback(\n\u001b[1;32m-> 1368\u001b[1;33m             self, etype, value, tb, tb_offset, number_of_lines_of_context)\n\u001b[0m\u001b[0;32m   1369\u001b[0m \u001b[1;33m\u001b[0m\u001b[0m\n\u001b[0;32m   1370\u001b[0m \u001b[1;33m\u001b[0m\u001b[0m\n",
      "\u001b[1;32m~\\.conda\\envs\\firma\\lib\\site-packages\\IPython\\core\\ultratb.py\u001b[0m in \u001b[0;36mstructured_traceback\u001b[1;34m(self, etype, value, tb, tb_offset, number_of_lines_of_context)\u001b[0m\n\u001b[0;32m   1266\u001b[0m             \u001b[1;31m# Verbose modes need a full traceback\u001b[0m\u001b[1;33m\u001b[0m\u001b[1;33m\u001b[0m\u001b[1;33m\u001b[0m\u001b[0m\n\u001b[0;32m   1267\u001b[0m             return VerboseTB.structured_traceback(\n\u001b[1;32m-> 1268\u001b[1;33m                 \u001b[0mself\u001b[0m\u001b[1;33m,\u001b[0m \u001b[0metype\u001b[0m\u001b[1;33m,\u001b[0m \u001b[0mvalue\u001b[0m\u001b[1;33m,\u001b[0m \u001b[0mtb\u001b[0m\u001b[1;33m,\u001b[0m \u001b[0mtb_offset\u001b[0m\u001b[1;33m,\u001b[0m \u001b[0mnumber_of_lines_of_context\u001b[0m\u001b[1;33m\u001b[0m\u001b[1;33m\u001b[0m\u001b[0m\n\u001b[0m\u001b[0;32m   1269\u001b[0m             )\n\u001b[0;32m   1270\u001b[0m         \u001b[1;32melif\u001b[0m \u001b[0mmode\u001b[0m \u001b[1;33m==\u001b[0m \u001b[1;34m'Minimal'\u001b[0m\u001b[1;33m:\u001b[0m\u001b[1;33m\u001b[0m\u001b[1;33m\u001b[0m\u001b[0m\n",
      "\u001b[1;32m~\\.conda\\envs\\firma\\lib\\site-packages\\IPython\\core\\ultratb.py\u001b[0m in \u001b[0;36mstructured_traceback\u001b[1;34m(self, etype, evalue, etb, tb_offset, number_of_lines_of_context)\u001b[0m\n\u001b[0;32m   1123\u001b[0m \u001b[1;33m\u001b[0m\u001b[0m\n\u001b[0;32m   1124\u001b[0m         formatted_exception = self.format_exception_as_a_whole(etype, evalue, etb, number_of_lines_of_context,\n\u001b[1;32m-> 1125\u001b[1;33m                                                                tb_offset)\n\u001b[0m\u001b[0;32m   1126\u001b[0m \u001b[1;33m\u001b[0m\u001b[0m\n\u001b[0;32m   1127\u001b[0m         \u001b[0mcolors\u001b[0m \u001b[1;33m=\u001b[0m \u001b[0mself\u001b[0m\u001b[1;33m.\u001b[0m\u001b[0mColors\u001b[0m  \u001b[1;31m# just a shorthand + quicker name lookup\u001b[0m\u001b[1;33m\u001b[0m\u001b[1;33m\u001b[0m\u001b[0m\n",
      "\u001b[1;32m~\\.conda\\envs\\firma\\lib\\site-packages\\IPython\\core\\ultratb.py\u001b[0m in \u001b[0;36mformat_exception_as_a_whole\u001b[1;34m(self, etype, evalue, etb, number_of_lines_of_context, tb_offset)\u001b[0m\n\u001b[0;32m   1080\u001b[0m \u001b[1;33m\u001b[0m\u001b[0m\n\u001b[0;32m   1081\u001b[0m \u001b[1;33m\u001b[0m\u001b[0m\n\u001b[1;32m-> 1082\u001b[1;33m         \u001b[0mlast_unique\u001b[0m\u001b[1;33m,\u001b[0m \u001b[0mrecursion_repeat\u001b[0m \u001b[1;33m=\u001b[0m \u001b[0mfind_recursion\u001b[0m\u001b[1;33m(\u001b[0m\u001b[0morig_etype\u001b[0m\u001b[1;33m,\u001b[0m \u001b[0mevalue\u001b[0m\u001b[1;33m,\u001b[0m \u001b[0mrecords\u001b[0m\u001b[1;33m)\u001b[0m\u001b[1;33m\u001b[0m\u001b[1;33m\u001b[0m\u001b[0m\n\u001b[0m\u001b[0;32m   1083\u001b[0m \u001b[1;33m\u001b[0m\u001b[0m\n\u001b[0;32m   1084\u001b[0m         \u001b[0mframes\u001b[0m \u001b[1;33m=\u001b[0m \u001b[0mself\u001b[0m\u001b[1;33m.\u001b[0m\u001b[0mformat_records\u001b[0m\u001b[1;33m(\u001b[0m\u001b[0mrecords\u001b[0m\u001b[1;33m,\u001b[0m \u001b[0mlast_unique\u001b[0m\u001b[1;33m,\u001b[0m \u001b[0mrecursion_repeat\u001b[0m\u001b[1;33m)\u001b[0m\u001b[1;33m\u001b[0m\u001b[1;33m\u001b[0m\u001b[0m\n",
      "\u001b[1;32m~\\.conda\\envs\\firma\\lib\\site-packages\\IPython\\core\\ultratb.py\u001b[0m in \u001b[0;36mfind_recursion\u001b[1;34m(etype, value, records)\u001b[0m\n\u001b[0;32m    380\u001b[0m     \u001b[1;31m# first frame (from in to out) that looks different.\u001b[0m\u001b[1;33m\u001b[0m\u001b[1;33m\u001b[0m\u001b[1;33m\u001b[0m\u001b[0m\n\u001b[0;32m    381\u001b[0m     \u001b[1;32mif\u001b[0m \u001b[1;32mnot\u001b[0m \u001b[0mis_recursion_error\u001b[0m\u001b[1;33m(\u001b[0m\u001b[0metype\u001b[0m\u001b[1;33m,\u001b[0m \u001b[0mvalue\u001b[0m\u001b[1;33m,\u001b[0m \u001b[0mrecords\u001b[0m\u001b[1;33m)\u001b[0m\u001b[1;33m:\u001b[0m\u001b[1;33m\u001b[0m\u001b[1;33m\u001b[0m\u001b[0m\n\u001b[1;32m--> 382\u001b[1;33m         \u001b[1;32mreturn\u001b[0m \u001b[0mlen\u001b[0m\u001b[1;33m(\u001b[0m\u001b[0mrecords\u001b[0m\u001b[1;33m)\u001b[0m\u001b[1;33m,\u001b[0m \u001b[1;36m0\u001b[0m\u001b[1;33m\u001b[0m\u001b[1;33m\u001b[0m\u001b[0m\n\u001b[0m\u001b[0;32m    383\u001b[0m \u001b[1;33m\u001b[0m\u001b[0m\n\u001b[0;32m    384\u001b[0m     \u001b[1;31m# Select filename, lineno, func_name to track frames with\u001b[0m\u001b[1;33m\u001b[0m\u001b[1;33m\u001b[0m\u001b[1;33m\u001b[0m\u001b[0m\n",
      "\u001b[1;31mTypeError\u001b[0m: object of type 'NoneType' has no len()"
     ]
    }
   ],
   "source": [
    "class Ssh:\n",
    "\n",
    "    def __init__(self):\n",
    "\n",
    "        self.HOST = ''\n",
    "\n",
    "        self.USERNAME = ''\n",
    "\n",
    "        self.PASSWORD = ''\n",
    "\n",
    "        self.CLIENT = None\n",
    "\n",
    "    def conecta(self):\n",
    "\n",
    "        try:\n",
    "\n",
    "            self.HOST = input('Nombre o ip del host: ')\n",
    "\n",
    "            self.USERNAME = input('Usuario: ')\n",
    "\n",
    "            self.PASSWORD = getpass.getpass()\n",
    "\n",
    "        except:\n",
    "\n",
    "            print('Error al introducir alguno de los datos')\n",
    "\n",
    "            sys.exit(1)\n",
    "\n",
    "        try:\n",
    "\n",
    "            # Conectamos por ssh\n",
    "\n",
    "            self.CLIENT = paramiko.SSHClient()\n",
    "\n",
    "            self.CLIENT.set_missing_host_key_policy(paramiko.AutoAddPolicy())\n",
    "\n",
    "            self.CLIENT.load_system_host_keys()\n",
    "\n",
    "            self.CLIENT.connect( hostname = self.HOST , username = self.USERNAME , password = self.PASSWORD )\n",
    "\n",
    "        except:\n",
    "\n",
    "            print('Error en la conexión')\n",
    "\n",
    "            sys.exit(1)\n",
    "\n",
    "        # Invocamos el shell para ejecutar comandos remotos\n",
    "\n",
    "        try:\n",
    "\n",
    "            shell = self.CLIENT.invoke_shell()\n",
    "\n",
    "            try:\n",
    "\n",
    "                # Ejecutamos el comando remoto\n",
    "\n",
    "                stdin, stdout, stderr = self.CLIENT.exec_command( 'uname -a' , bufsize = -1 , timeout = None , get_pty = True , environment = None)\n",
    "\n",
    "                # Mostramos la salida estandar línea por línea\n",
    "\n",
    "                for line in iter(stdout.readline, \"\"):\n",
    "\n",
    "                    print(line, end=\"\")\n",
    "\n",
    "            except:\n",
    "\n",
    "                print('Error: al ejecutar el comando')\n",
    "\n",
    "                sys.exit(1)\n",
    "\n",
    "        except:\n",
    "\n",
    "            print('Error en la conexión por ssh')\n",
    "\n",
    "            sys.exit(1)\n",
    "\n",
    "        # Cerramos el shell\n",
    "\n",
    "        shell.close()\n",
    "\n",
    "        # ------------------------------------------------------------------\n",
    "\n",
    "        self.CLIENT.close()\n",
    "\n",
    "if __name__ == '__main__':\n",
    "\n",
    "    ssh = Ssh()\n",
    "\n",
    "    ssh.conecta()"
   ]
  },
  {
   "cell_type": "code",
   "execution_count": null,
   "id": "feb32d81",
   "metadata": {},
   "outputs": [],
   "source": []
  }
 ],
 "metadata": {
  "kernelspec": {
   "display_name": "Python 3 (ipykernel)",
   "language": "python",
   "name": "python3"
  },
  "language_info": {
   "codemirror_mode": {
    "name": "ipython",
    "version": 3
   },
   "file_extension": ".py",
   "mimetype": "text/x-python",
   "name": "python",
   "nbconvert_exporter": "python",
   "pygments_lexer": "ipython3",
   "version": "3.7.5"
  }
 },
 "nbformat": 4,
 "nbformat_minor": 5
}
